{
    "docs": "https://docs.ansible.com/ansible-core/2.15/dev_guide/testing/sanity/import.html", 
    "results": [
        {
            "message": "The test `ansible-test sanity --test import --python 3.11` [[explain](https://docs.ansible.com/ansible-core/2.15/dev_guide/testing/sanity/import.html)] failed with 6 errors:", 
            "output": "plugins/module_utils/sonicos_core_functions.py:0:0: traceback: ValueError: collection metadata was not loaded for collection hornjo.sonicos\nplugins/modules/sonicos_address_groups.py:0:0: traceback: ValueError: collection metadata was not loaded for collection hornjo.sonicos\nplugins/modules/sonicos_address_objects.py:0:0: traceback: ValueError: collection metadata was not loaded for collection hornjo.sonicos\nplugins/modules/sonicos_service_groups.py:0:0: traceback: ValueError: collection metadata was not loaded for collection hornjo.sonicos\nplugins/modules/sonicos_service_objects.py:0:0: traceback: ValueError: collection metadata was not loaded for collection hornjo.sonicos\nplugins/modules/sonicos_zones.py:0:0: traceback: ValueError: collection metadata was not loaded for collection hornjo.sonicos"
        }
    ], 
    "verified": false
}
